2023-09-04 16:02:34 [INFO] [server.py] - Started server process [[36m23545[0m]
2023-09-04 16:02:34 [INFO] [on.py] - Waiting for application startup.
2023-09-04 16:02:34 [INFO] [on.py] - Application startup complete.
2023-09-04 16:02:34 [INFO] [server.py] - Uvicorn running on [1mhttp://0.0.0.0:8000[0m (Press CTRL+C to quit)
2023-09-04 16:03:04 [INFO] [server.py] - Shutting down
2023-09-04 16:03:04 [INFO] [on.py] - Waiting for application shutdown.
2023-09-04 16:03:04 [INFO] [on.py] - Application shutdown complete.
2023-09-04 16:03:04 [INFO] [server.py] - Finished server process [[36m23545[0m]
2023-09-20 17:39:00 [INFO] [server.py] - Started server process [[36m5923[0m]
2023-09-20 17:39:00 [INFO] [on.py] - Waiting for application startup.
2023-09-20 17:39:00 [INFO] [on.py] - Application startup complete.
2023-09-20 17:39:00 [INFO] [server.py] - Uvicorn running on [1mhttp://0.0.0.0:8000[0m (Press CTRL+C to quit)
2023-09-20 17:39:12 [INFO] [server.py] - Shutting down
2023-09-20 17:39:12 [INFO] [on.py] - Waiting for application shutdown.
2023-09-20 17:39:12 [INFO] [on.py] - Application shutdown complete.
2023-09-20 17:39:12 [INFO] [server.py] - Finished server process [[36m5923[0m]
2023-10-08 12:26:58 [INFO] [server.py] - Started server process [[36m7682[0m]
2023-10-08 12:26:58 [INFO] [on.py] - Waiting for application startup.
2023-10-08 12:26:58 [INFO] [on.py] - Application startup complete.
2023-10-08 12:26:58 [INFO] [server.py] - Uvicorn running on [1mhttp://0.0.0.0:8000[0m (Press CTRL+C to quit)
2023-10-08 12:27:08 [ERROR] [httptools_impl.py] - Exception in ASGI application
Traceback (most recent call last):
  File "/home/moongtnt/.local/lib/python3.10/site-packages/pandas/core/indexes/base.py", line 3653, in get_loc
    return self._engine.get_loc(casted_key)
  File "pandas/_libs/index.pyx", line 147, in pandas._libs.index.IndexEngine.get_loc
  File "pandas/_libs/index.pyx", line 176, in pandas._libs.index.IndexEngine.get_loc
  File "pandas/_libs/hashtable_class_helper.pxi", line 7080, in pandas._libs.hashtable.PyObjectHashTable.get_item
  File "pandas/_libs/hashtable_class_helper.pxi", line 7088, in pandas._libs.hashtable.PyObjectHashTable.get_item
KeyError: 'cybr'

The above exception was the direct cause of the following exception:

Traceback (most recent call last):
  File "/home/moongtnt/.local/lib/python3.10/site-packages/uvicorn/protocols/http/httptools_impl.py", line 435, in run_asgi
    result = await app(  # type: ignore[func-returns-value]
  File "/home/moongtnt/.local/lib/python3.10/site-packages/uvicorn/middleware/proxy_headers.py", line 78, in __call__
    return await self.app(scope, receive, send)
  File "/home/moongtnt/.local/lib/python3.10/site-packages/fastapi/applications.py", line 276, in __call__
    await super().__call__(scope, receive, send)
  File "/home/moongtnt/.local/lib/python3.10/site-packages/starlette/applications.py", line 122, in __call__
    await self.middleware_stack(scope, receive, send)
  File "/home/moongtnt/.local/lib/python3.10/site-packages/starlette/middleware/errors.py", line 184, in __call__
    raise exc
  File "/home/moongtnt/.local/lib/python3.10/site-packages/starlette/middleware/errors.py", line 162, in __call__
    await self.app(scope, receive, _send)
  File "/home/moongtnt/.local/lib/python3.10/site-packages/starlette/middleware/cors.py", line 83, in __call__
    await self.app(scope, receive, send)
  File "/home/moongtnt/.local/lib/python3.10/site-packages/starlette/middleware/exceptions.py", line 79, in __call__
    raise exc
  File "/home/moongtnt/.local/lib/python3.10/site-packages/starlette/middleware/exceptions.py", line 68, in __call__
    await self.app(scope, receive, sender)
  File "/home/moongtnt/.local/lib/python3.10/site-packages/fastapi/middleware/asyncexitstack.py", line 21, in __call__
    raise e
  File "/home/moongtnt/.local/lib/python3.10/site-packages/fastapi/middleware/asyncexitstack.py", line 18, in __call__
    await self.app(scope, receive, send)
  File "/home/moongtnt/.local/lib/python3.10/site-packages/starlette/routing.py", line 718, in __call__
    await route.handle(scope, receive, send)
  File "/home/moongtnt/.local/lib/python3.10/site-packages/starlette/routing.py", line 276, in handle
    await self.app(scope, receive, send)
  File "/home/moongtnt/.local/lib/python3.10/site-packages/starlette/routing.py", line 66, in app
    response = await func(request)
  File "/home/moongtnt/.local/lib/python3.10/site-packages/fastapi/routing.py", line 237, in app
    raw_response = await run_endpoint_function(
  File "/home/moongtnt/.local/lib/python3.10/site-packages/fastapi/routing.py", line 165, in run_endpoint_function
    return await run_in_threadpool(dependant.call, **values)
  File "/home/moongtnt/.local/lib/python3.10/site-packages/starlette/concurrency.py", line 41, in run_in_threadpool
    return await anyio.to_thread.run_sync(func, *args)
  File "/home/moongtnt/.local/lib/python3.10/site-packages/anyio/to_thread.py", line 33, in run_sync
    return await get_asynclib().run_sync_in_worker_thread(
  File "/home/moongtnt/.local/lib/python3.10/site-packages/anyio/_backends/_asyncio.py", line 877, in run_sync_in_worker_thread
    return await future
  File "/home/moongtnt/.local/lib/python3.10/site-packages/anyio/_backends/_asyncio.py", line 807, in run
    result = context.run(func, *args)
  File "/home/moongtnt/final_test/miraeasset-GPT/main.py", line 81, in get_stk_filtering
    momentum_tuple_list = get_momentums(filter_list=filter_list)
  File "/home/moongtnt/final_test/miraeasset-GPT/core/financial_filtering.py", line 51, in get_momentums
    kratio = get_k_ratio(prices_df=prices_df[t.lower()])
  File "/home/moongtnt/.local/lib/python3.10/site-packages/pandas/core/frame.py", line 3761, in __getitem__
    indexer = self.columns.get_loc(key)
  File "/home/moongtnt/.local/lib/python3.10/site-packages/pandas/core/indexes/base.py", line 3655, in get_loc
    raise KeyError(key) from err
KeyError: 'cybr'
2023-10-08 12:27:17 [ERROR] [httptools_impl.py] - Exception in ASGI application
Traceback (most recent call last):
  File "/home/moongtnt/.local/lib/python3.10/site-packages/pandas/core/indexes/base.py", line 3653, in get_loc
    return self._engine.get_loc(casted_key)
  File "pandas/_libs/index.pyx", line 147, in pandas._libs.index.IndexEngine.get_loc
  File "pandas/_libs/index.pyx", line 176, in pandas._libs.index.IndexEngine.get_loc
  File "pandas/_libs/hashtable_class_helper.pxi", line 7080, in pandas._libs.hashtable.PyObjectHashTable.get_item
  File "pandas/_libs/hashtable_class_helper.pxi", line 7088, in pandas._libs.hashtable.PyObjectHashTable.get_item
KeyError: 'cybr'

The above exception was the direct cause of the following exception:

Traceback (most recent call last):
  File "/home/moongtnt/.local/lib/python3.10/site-packages/uvicorn/protocols/http/httptools_impl.py", line 435, in run_asgi
    result = await app(  # type: ignore[func-returns-value]
  File "/home/moongtnt/.local/lib/python3.10/site-packages/uvicorn/middleware/proxy_headers.py", line 78, in __call__
    return await self.app(scope, receive, send)
  File "/home/moongtnt/.local/lib/python3.10/site-packages/fastapi/applications.py", line 276, in __call__
    await super().__call__(scope, receive, send)
  File "/home/moongtnt/.local/lib/python3.10/site-packages/starlette/applications.py", line 122, in __call__
    await self.middleware_stack(scope, receive, send)
  File "/home/moongtnt/.local/lib/python3.10/site-packages/starlette/middleware/errors.py", line 184, in __call__
    raise exc
  File "/home/moongtnt/.local/lib/python3.10/site-packages/starlette/middleware/errors.py", line 162, in __call__
    await self.app(scope, receive, _send)
  File "/home/moongtnt/.local/lib/python3.10/site-packages/starlette/middleware/cors.py", line 83, in __call__
    await self.app(scope, receive, send)
  File "/home/moongtnt/.local/lib/python3.10/site-packages/starlette/middleware/exceptions.py", line 79, in __call__
    raise exc
  File "/home/moongtnt/.local/lib/python3.10/site-packages/starlette/middleware/exceptions.py", line 68, in __call__
    await self.app(scope, receive, sender)
  File "/home/moongtnt/.local/lib/python3.10/site-packages/fastapi/middleware/asyncexitstack.py", line 21, in __call__
    raise e
  File "/home/moongtnt/.local/lib/python3.10/site-packages/fastapi/middleware/asyncexitstack.py", line 18, in __call__
    await self.app(scope, receive, send)
  File "/home/moongtnt/.local/lib/python3.10/site-packages/starlette/routing.py", line 718, in __call__
    await route.handle(scope, receive, send)
  File "/home/moongtnt/.local/lib/python3.10/site-packages/starlette/routing.py", line 276, in handle
    await self.app(scope, receive, send)
  File "/home/moongtnt/.local/lib/python3.10/site-packages/starlette/routing.py", line 66, in app
    response = await func(request)
  File "/home/moongtnt/.local/lib/python3.10/site-packages/fastapi/routing.py", line 237, in app
    raw_response = await run_endpoint_function(
  File "/home/moongtnt/.local/lib/python3.10/site-packages/fastapi/routing.py", line 165, in run_endpoint_function
    return await run_in_threadpool(dependant.call, **values)
  File "/home/moongtnt/.local/lib/python3.10/site-packages/starlette/concurrency.py", line 41, in run_in_threadpool
    return await anyio.to_thread.run_sync(func, *args)
  File "/home/moongtnt/.local/lib/python3.10/site-packages/anyio/to_thread.py", line 33, in run_sync
    return await get_asynclib().run_sync_in_worker_thread(
  File "/home/moongtnt/.local/lib/python3.10/site-packages/anyio/_backends/_asyncio.py", line 877, in run_sync_in_worker_thread
    return await future
  File "/home/moongtnt/.local/lib/python3.10/site-packages/anyio/_backends/_asyncio.py", line 807, in run
    result = context.run(func, *args)
  File "/home/moongtnt/final_test/miraeasset-GPT/main.py", line 81, in get_stk_filtering
    momentum_tuple_list = get_momentums(filter_list=filter_list)
  File "/home/moongtnt/final_test/miraeasset-GPT/core/financial_filtering.py", line 51, in get_momentums
    kratio = get_k_ratio(prices_df=prices_df[t.lower()])
  File "/home/moongtnt/.local/lib/python3.10/site-packages/pandas/core/frame.py", line 3761, in __getitem__
    indexer = self.columns.get_loc(key)
  File "/home/moongtnt/.local/lib/python3.10/site-packages/pandas/core/indexes/base.py", line 3655, in get_loc
    raise KeyError(key) from err
KeyError: 'cybr'
2023-10-08 12:28:14 [INFO] [server.py] - Shutting down
2023-10-08 12:28:14 [INFO] [on.py] - Waiting for application shutdown.
2023-10-08 12:28:14 [INFO] [on.py] - Application shutdown complete.
2023-10-08 12:28:14 [INFO] [server.py] - Finished server process [[36m7682[0m]
2023-10-08 12:28:17 [INFO] [server.py] - Started server process [[36m8075[0m]
2023-10-08 12:28:17 [INFO] [on.py] - Waiting for application startup.
2023-10-08 12:28:17 [INFO] [on.py] - Application startup complete.
2023-10-08 12:28:17 [INFO] [server.py] - Uvicorn running on [1mhttp://0.0.0.0:8000[0m (Press CTRL+C to quit)
2023-10-08 12:29:31 [INFO] [server.py] - Shutting down
2023-10-08 12:29:31 [INFO] [on.py] - Waiting for application shutdown.
2023-10-08 12:29:31 [INFO] [on.py] - Application shutdown complete.
2023-10-08 12:29:31 [INFO] [server.py] - Finished server process [[36m8075[0m]
